2021-12-13 19:50:28,710 INFO: Microblog startup [in /home/corey/Documents/Development/microblog/app/__init__.py:46]
2021-12-13 20:25:22,374 INFO: Microblog startup [in /home/corey/Documents/Development/microblog/app/__init__.py:48]
2021-12-13 20:25:35,474 INFO: Microblog startup [in /home/corey/Documents/Development/microblog/app/__init__.py:48]
2021-12-13 20:25:45,993 ERROR: Exception on /reset_password_request [POST] [in /home/corey/Documents/Development/microblog/venv/lib/python3.9/site-packages/flask/app.py:1457]
Traceback (most recent call last):
  File "/home/corey/Documents/Development/microblog/venv/lib/python3.9/site-packages/flask/app.py", line 2073, in wsgi_app
    response = self.full_dispatch_request()
  File "/home/corey/Documents/Development/microblog/venv/lib/python3.9/site-packages/flask/app.py", line 1518, in full_dispatch_request
    rv = self.handle_user_exception(e)
  File "/home/corey/Documents/Development/microblog/venv/lib/python3.9/site-packages/flask/app.py", line 1516, in full_dispatch_request
    rv = self.dispatch_request()
  File "/home/corey/Documents/Development/microblog/venv/lib/python3.9/site-packages/flask/app.py", line 1502, in dispatch_request
    return self.ensure_sync(self.view_functions[rule.endpoint])(**req.view_args)
  File "/home/corey/Documents/Development/microblog/app/routes.py", line 164, in reset_password_request
    send_password_reset_email(user)
  File "/home/corey/Documents/Development/microblog/app/email.py", line 14, in send_password_reset_email
    send_email('[Microblog] Reset Your Password',
NameError: name 'send_email' is not defined
2021-12-13 20:26:52,254 ERROR: Exception on /reset_password_request [POST] [in /home/corey/Documents/Development/microblog/venv/lib/python3.9/site-packages/flask/app.py:1457]
Traceback (most recent call last):
  File "/home/corey/Documents/Development/microblog/venv/lib/python3.9/site-packages/flask/app.py", line 2073, in wsgi_app
    response = self.full_dispatch_request()
  File "/home/corey/Documents/Development/microblog/venv/lib/python3.9/site-packages/flask/app.py", line 1518, in full_dispatch_request
    rv = self.handle_user_exception(e)
  File "/home/corey/Documents/Development/microblog/venv/lib/python3.9/site-packages/flask/app.py", line 1516, in full_dispatch_request
    rv = self.dispatch_request()
  File "/home/corey/Documents/Development/microblog/venv/lib/python3.9/site-packages/flask/app.py", line 1502, in dispatch_request
    return self.ensure_sync(self.view_functions[rule.endpoint])(**req.view_args)
  File "/home/corey/Documents/Development/microblog/app/routes.py", line 164, in reset_password_request
    send_password_reset_email(user)
  File "/home/corey/Documents/Development/microblog/app/email.py", line 14, in send_password_reset_email
    send_email('[Microblog] Reset Your Password',
NameError: name 'send_email' is not defined
2021-12-13 20:26:56,828 INFO: Microblog startup [in /home/corey/Documents/Development/microblog/app/__init__.py:48]
2021-12-13 20:27:06,254 ERROR: Exception on /reset_password_request [POST] [in /home/corey/Documents/Development/microblog/venv/lib/python3.9/site-packages/flask/app.py:1457]
Traceback (most recent call last):
  File "/home/corey/Documents/Development/microblog/venv/lib/python3.9/site-packages/flask/app.py", line 2073, in wsgi_app
    response = self.full_dispatch_request()
  File "/home/corey/Documents/Development/microblog/venv/lib/python3.9/site-packages/flask/app.py", line 1518, in full_dispatch_request
    rv = self.handle_user_exception(e)
  File "/home/corey/Documents/Development/microblog/venv/lib/python3.9/site-packages/flask/app.py", line 1516, in full_dispatch_request
    rv = self.dispatch_request()
  File "/home/corey/Documents/Development/microblog/venv/lib/python3.9/site-packages/flask/app.py", line 1502, in dispatch_request
    return self.ensure_sync(self.view_functions[rule.endpoint])(**req.view_args)
  File "/home/corey/Documents/Development/microblog/app/routes.py", line 164, in reset_password_request
    send_password_reset_email(user)
  File "/home/corey/Documents/Development/microblog/app/email.py", line 14, in send_password_reset_email
    send_email('[Microblog] Reset Your Password',
  File "/home/corey/Documents/Development/microblog/app/email.py", line 10, in send_email
    mail.send(msg)
  File "/home/corey/Documents/Development/microblog/venv/lib/python3.9/site-packages/flask_mail.py", line 491, in send
    with self.connect() as connection:
  File "/home/corey/Documents/Development/microblog/venv/lib/python3.9/site-packages/flask_mail.py", line 144, in __enter__
    self.host = self.configure_host()
  File "/home/corey/Documents/Development/microblog/venv/lib/python3.9/site-packages/flask_mail.py", line 158, in configure_host
    host = smtplib.SMTP(self.mail.server, self.mail.port)
  File "/usr/lib/python3.9/smtplib.py", line 255, in __init__
    (code, msg) = self.connect(host, port)
  File "/usr/lib/python3.9/smtplib.py", line 341, in connect
    self.sock = self._get_socket(host, port, self.timeout)
  File "/usr/lib/python3.9/smtplib.py", line 312, in _get_socket
    return socket.create_connection((host, port), timeout,
  File "/usr/lib/python3.9/socket.py", line 843, in create_connection
    raise err
  File "/usr/lib/python3.9/socket.py", line 831, in create_connection
    sock.connect(sa)
ConnectionRefusedError: [Errno 111] Connection refused
2021-12-13 20:27:35,043 INFO: Microblog startup [in /home/corey/Documents/Development/microblog/app/__init__.py:48]
